<?xml version="1.0" ?>
<robot name="angle_robot" xmlns:xacro="http://www.ros.org/wiki/xacro">
    <xacro:include filename="$(find angle_ax12_model_pkg)/urdf/angle_robot_ax12.gazebo" />

	<link name ="world"/>
	
	<joint name="ang12x_base_joint" type="fixed">
		<parent link="world"/>
		<child link="ang12ax_link0"/>
		<origin rpy = "0 0 0" xyz="0 0 0" />
	</joint>

	<link name="ang12ax_link0">
		<visual>
			<origin xyz="0.0 0 0.0" rpy="1.57 0 0"/>
			<geometry>
				<mesh filename="package://angle_ax12_model_pkg/meshes/base.dae" scale="0.001 0.001 0.001"/>
			</geometry>
		</visual>
		<collision>
			<origin xyz="0.0 0 0.0" rpy="1.57 0 0"/>
			<geometry>
				<mesh filename="package://angle_ax12_model_pkg/meshes/base.dae" scale="0.001 0.001 0.001"/>
			</geometry>
		</collision>
		<inertial>
			<origin xyz="0 0 0" rpy="1.57 0 0"/>
			<mass value="0.2"/>
			<inertia
				ixx="0.00552196561445819"
				ixy="7.9550614501301E-10"
				ixz="-1.34378458924839E-09"
				iyy="0.00352397447953875"
				iyz="-1.10071809773382E-08"
				izz="0.00553739792746489" />
		</inertial>
	</link>

	<joint name="ang12ax_joint1" type="continuous">
		<parent link="ang12ax_link0"/>
		<child link="ang12ax_link1"/>
		<origin xyz = "0 0 0.008" rpy="0 0 0" />
		<axis xyz="0 0 1" />
		
		<limit effort="5.0" velocity="5.0"/>
	</joint>

	<link name="ang12ax_link1">
		<visual>
			<origin xyz="0 0 0" rpy="1.57 0 1.57"/>
			<geometry>
				<mesh filename="package://angle_ax12_model_pkg/meshes/link1.dae" scale="0.001 0.001 0.001"/>
			</geometry>
		</visual>
		<collision>
			<origin xyz="0 0 0" rpy="1.57 0 1.57"/>
			<geometry>
				<mesh filename="package://angle_ax12_model_pkg/meshes/link1.dae" scale="0.001 0.001 0.001"/>
			</geometry>
		</collision>
		<inertial>
			<origin xyz="0 -0.005 0.037" rpy="1.57 0 1.57"/>
			<mass value="0.25"/>
			<inertia
				ixx="0.00552196561445819"
				ixy="7.9550614501301E-10"
				ixz="-1.34378458924839E-09"
				iyy="0.00352397447953875"
				iyz="-1.10071809773382E-08"
				izz="0.00553739792746489" />
			</inertial>
	</link>

	<joint name="ang12ax_joint2" type="continuous">
		<parent link="ang12ax_link1"/>
		<child link="ang12ax_link2"/>
		<origin xyz = "0 0.0151 0.061" rpy="0 0 0" />
		<axis xyz="0 -1 0" />
		
		<limit effort="5.0" velocity="5.0"/>
	</joint>

	<link name="ang12ax_link2">
		<visual>
			<origin xyz="0.0 0.0 0.0" rpy="1.57 0 1.57"/>
			<geometry>
				<mesh filename="package://angle_ax12_model_pkg/meshes/link2.dae" scale="0.001 0.001 0.001"/>
			</geometry>
		</visual>
		<collision>
			<origin xyz="0.0 0.0 0.0" rpy="1.57 0 1.57"/>
			<geometry>
				<mesh filename="package://angle_ax12_model_pkg/meshes/link2.dae" scale="0.001 0.001 0.001"/>
			</geometry>
		</collision>
		<inertial>
			<origin xyz="0.0 -0.01794 0.06" rpy="1.57 0 1.57"/>
			<mass value="0.2"/>
			<inertia
				ixx="0.0012474"
				ixy="-5.4004E-07"
				ixz="-0.0013148"
				iyy="0.0072923"
				iyz="-1.8586E-07"
				izz="0.0068178" />
		</inertial>
	</link>

	<joint name="ang12ax_joint3" type="continuous">
		<parent link="ang12ax_link2"/>
		<child link="ang12ax_link3"/>
		<origin xyz = "0.0 -0.0082 0.08" rpy="0 0 0" />
		<axis xyz="0 -1 0" />
		
		<limit effort="5.0" velocity="5.0"/>
	</joint>

	<link name="ang12ax_link3">
		<visual>
			<origin xyz="0.0 0.0 0.0" rpy="0 0 1.57"/>
			<geometry>
				<mesh filename="package://angle_ax12_model_pkg/meshes/link3.dae" scale="0.001 0.001 0.001"/>
			</geometry>
		</visual>
		<collision>
			<origin xyz="0.0 0.0 0.0" rpy="0 0 1.57"/>
			<geometry>
				<mesh filename="package://angle_ax12_model_pkg/meshes/link3.dae" scale="0.001 0.001 0.001"/>
			</geometry>
		</collision>
		<inertial>
			<origin xyz="0.0 -0.012 0.096" rpy="1.57 0 1.57"/>
			<mass value="0.25"/>
			<inertia
				ixx="0.00104290750143942"
				ixy="4.37155302268076E-09"
				ixz="-2.45049603914627E-09"
				iyy="0.000380518373895034"
				iyz="-7.56009835172156E-09"
				izz="0.00106006525067445" />
		</inertial>
	</link>

	<joint name="ang12ax_joint4" type="continuous">
		<parent link="ang12ax_link3"/>
		<child link="ang12ax_link4"/>
		<origin xyz = "0.0 -0.0078 0.12" rpy="0 0 0" />
		<axis xyz="0 -1 0" />
		
		<limit effort="5.0" velocity="5.0"/>
	</joint>

	<link name="ang12ax_link4">
		<visual>
			<origin xyz="0.0 0.0 0.0" rpy="0 0 1.57"/>
			<geometry>
				<mesh filename="package://angle_ax12_model_pkg/meshes/link4.dae" scale="0.001 0.001 0.001"/>
			</geometry>
		</visual>
		<collision>
			<origin xyz="0.0 0.0 0.0" rpy="0 0 1.57"/>
			<geometry>
				<mesh filename="package://angle_ax12_model_pkg/meshes/link4.dae" scale="0.001 0.001 0.001"/>
			</geometry>
		</collision>
		<inertial>
			<origin xyz="0.0 0.0 0.032" rpy="0 0 0"/>
			<mass value="0.2"/>
			<inertia
				ixx="0.00079656"
				ixy="-7.8011E-10"
				ixz="0.00053616"
				iyy="0.003576"
				iyz="4.6326E-10"
				izz="0.0033698" />
		</inertial>
	</link>

	<joint name="ang12ax_joint5" type="continuous">
		<parent link="ang12ax_link4"/>
		<child link="ang12ax_link5"/>
		<origin xyz = "0.0 0.0 0.05694" rpy="0 0 0" />
		<axis xyz="0 0 1" />
		
		<limit effort="5.0" velocity="5.0"/>
	</joint>

	<link name="ang12ax_link5">
		<visual>
			<origin xyz="0.0 0.0 0.0" rpy="0 0 1.57"/>
			<geometry>
				<mesh filename="package://angle_ax12_model_pkg/meshes/link5.dae" scale="0.001 0.001 0.001"/>
			</geometry>
		</visual>
		<collision>
			<origin xyz="0.0 0.0 0.0" rpy="0 0 1.57"/>
			<geometry>
				<mesh filename="package://angle_ax12_model_pkg/meshes/link5.dae" scale="0.001 0.001 0.001"/>
			</geometry>
		</collision>
		<inertial>
			<origin xyz="0.0 0.0 0.0" rpy="0 0 0"/>
			<mass value="0.12"/>
			<inertia
				ixx="0.00104290750143942"
				ixy="4.37155302268076E-09"
				ixz="-2.45049603914627E-09"
				iyy="0.000380518373895034"
				iyz="-7.56009835172156E-09"
				izz="0.00106006525067445" />
		</inertial>
	</link>

	<joint name="ang12ax_grip_joint1" type="fixed">
		<parent link="ang12ax_link5"/>
		<child link="ang12ax_link_grip_1"/>
		<origin xyz = "0.013 0.012 0.02025" rpy="0 0 0" />
	</joint>

	<link name="ang12ax_link_grip_1">
		<visual>
			<origin xyz="0.0 0.0 0.0" rpy="0 0 1.57"/>
			<geometry>
				<mesh filename="package://angle_ax12_model_pkg/meshes/link_g1.dae" scale="0.001 0.001 0.001"/>
			</geometry>
		</visual>
		<collision>
			<origin xyz="0.0 0.0 0.0" rpy="0 0 1.57"/>
			<geometry>
				<mesh filename="package://angle_ax12_model_pkg/meshes/link_g1.dae" scale="0.001 0.001 0.001"/>
			</geometry>
		</collision>
		<inertial>
			<origin xyz="0.0 0.0 0.0" rpy="0 0 0"/>
			<mass value="0.01"/>
			<inertia
				ixx="0.00104290750143942"
				ixy="4.37155302268076E-09"
				ixz="-2.45049603914627E-09"
				iyy="0.000380518373895034"
				iyz="-7.56009835172156E-09"
				izz="0.00106006525067445" />
		</inertial>
	</link>

	<joint name="ang12ax_grip_joint_left" type="prismatic">
		<parent link="ang12ax_link_grip_1"/>
		<child link="ang12ax_link_grip_left"/>
		<limit effort="2" lower="0" upper="0.026" velocity="0.02"/>
		<axis xyz="0 -1 0" />
		<origin xyz = "-0.0035 0.020 0.028914" rpy="0 0 0" />
	</joint>

	<link name="ang12ax_link_grip_left">
		<visual>
			<origin xyz="0.0 0.0 0.0" rpy="0 0 -1.57"/>
			<geometry>
				<mesh filename="package://angle_ax12_model_pkg/meshes/link_g2.dae" scale="0.001 0.001 0.001"/>
			</geometry>
		</visual>
		<collision>
			<origin xyz="0.0 0.0 0.0" rpy="0 0 -1.57"/>
			<geometry>
				<mesh filename="package://angle_ax12_model_pkg/meshes/link_g2.dae" scale="0.001 0.001 0.001"/>
			</geometry>
		</collision>
		<inertial>
			<origin xyz="0.0 0.0 0.0" rpy="0 0 0"/>
			<mass value="0.01"/>
			<inertia
				ixx="0.00104290750143942"
				ixy="4.37155302268076E-09"
				ixz="-2.45049603914627E-09"
				iyy="0.000380518373895034"
				iyz="-7.56009835172156E-09"
				izz="0.00106006525067445" />
		</inertial>
	</link>

	<joint name="ang12ax_grip_joint_right" type="prismatic">
		<parent link="ang12ax_link_grip_1"/>
		<child link="ang12ax_link_grip_right"/>
		<limit effort="2" lower="0" upper="0.026" velocity="0.02"/>
		<axis xyz="0 1 0" />
		<origin xyz = "0.0005 -0.044 0.028914" rpy="0 0 0" />
	</joint>

	<link name="ang12ax_link_grip_right">
		<visual>
			<origin xyz="0.0 0.0 0.0" rpy="0 0 1.57"/>
			<geometry>
				<mesh filename="package://angle_ax12_model_pkg/meshes/link_g2.dae" scale="0.001 0.001 0.001"/>
			</geometry>
		</visual>
		<collision>
			<origin xyz="0.0 0.0 0.0" rpy="0 0 1.57"/>
			<geometry>
				<mesh filename="package://angle_ax12_model_pkg/meshes/link_g2.dae" scale="0.001 0.001 0.001"/>
			</geometry>
		</collision>
		<inertial>
			<origin xyz="0.0 0.0 0.0" rpy="0 0 0"/>
			<mass value="0.01"/>
			<inertia
				ixx="0.00104290750143942"
				ixy="4.37155302268076E-09"
				ixz="-2.45049603914627E-09"
				iyy="0.000380518373895034"
				iyz="-7.56009835172156E-09"
				izz="0.00106006525067445" />
		</inertial>
	</link>

	<xacro:arm_transmission prefix="ang12ax_joint1"/>
	<xacro:arm_transmission prefix="ang12ax_joint2"/>
	<xacro:arm_transmission prefix="ang12ax_joint3"/>
	<xacro:arm_transmission prefix="ang12ax_joint4"/>
	<xacro:arm_transmission prefix="ang12ax_joint5"/>

	<xacro:SimpleTransmissionEffort prefix="ang12ax_grip_joint_left"/>
	<xacro:SimpleTransmissionEffort prefix="ang12ax_grip_joint_right"/>

</robot>